2020-11-03 13:49:47 [django.request:135] [ERROR] - Internal Server Error: /admin/login/
Traceback (most recent call last):
  File "/data/cmdb/env_py36/lib/python3.6/site-packages/django/core/handlers/exception.py", line 41, in inner
    response = get_response(request)
  File "/data/cmdb/env_py36/lib/python3.6/site-packages/django/core/handlers/base.py", line 217, in _get_response
    response = self.process_exception_by_middleware(e, request)
  File "/data/cmdb/env_py36/lib/python3.6/site-packages/django/core/handlers/base.py", line 215, in _get_response
    response = response.render()
  File "/data/cmdb/env_py36/lib/python3.6/site-packages/django/template/response.py", line 107, in render
    self.content = self.rendered_content
  File "/data/cmdb/env_py36/lib/python3.6/site-packages/django/template/response.py", line 82, in rendered_content
    template = self.resolve_template(self.template_name)
  File "/data/cmdb/env_py36/lib/python3.6/site-packages/django/template/response.py", line 64, in resolve_template
    return select_template(template, using=self.using)
  File "/data/cmdb/env_py36/lib/python3.6/site-packages/django/template/loader.py", line 53, in select_template
    raise TemplateDoesNotExist(', '.join(template_name_list), chain=chain)
django.template.exceptions.TemplateDoesNotExist: admin/login.html
2020-11-03 13:49:49 [django.request:135] [ERROR] - Internal Server Error: /admin/login/
Traceback (most recent call last):
  File "/data/cmdb/env_py36/lib/python3.6/site-packages/django/core/handlers/exception.py", line 41, in inner
    response = get_response(request)
  File "/data/cmdb/env_py36/lib/python3.6/site-packages/django/core/handlers/base.py", line 217, in _get_response
    response = self.process_exception_by_middleware(e, request)
  File "/data/cmdb/env_py36/lib/python3.6/site-packages/django/core/handlers/base.py", line 215, in _get_response
    response = response.render()
  File "/data/cmdb/env_py36/lib/python3.6/site-packages/django/template/response.py", line 107, in render
    self.content = self.rendered_content
  File "/data/cmdb/env_py36/lib/python3.6/site-packages/django/template/response.py", line 82, in rendered_content
    template = self.resolve_template(self.template_name)
  File "/data/cmdb/env_py36/lib/python3.6/site-packages/django/template/response.py", line 64, in resolve_template
    return select_template(template, using=self.using)
  File "/data/cmdb/env_py36/lib/python3.6/site-packages/django/template/loader.py", line 53, in select_template
    raise TemplateDoesNotExist(', '.join(template_name_list), chain=chain)
django.template.exceptions.TemplateDoesNotExist: admin/login.html
2020-11-03 13:53:26 [django.request:152] [WARNING] - Not Found: /admin/
2020-11-03 13:54:31 [django.request:135] [ERROR] - Internal Server Error: /menus/
Traceback (most recent call last):
  File "/data/cmdb/env_py36/lib/python3.6/site-packages/django/db/backends/utils.py", line 64, in execute
    return self.cursor.execute(sql, params)
  File "/data/cmdb/env_py36/lib/python3.6/site-packages/django/db/backends/mysql/base.py", line 101, in execute
    return self.cursor.execute(query, args)
  File "/data/cmdb/env_py36/lib/python3.6/site-packages/pymysql/cursors.py", line 163, in execute
    result = self._query(query)
  File "/data/cmdb/env_py36/lib/python3.6/site-packages/pymysql/cursors.py", line 321, in _query
    conn.query(q)
  File "/data/cmdb/env_py36/lib/python3.6/site-packages/pymysql/connections.py", line 505, in query
    self._affected_rows = self._read_query_result(unbuffered=unbuffered)
  File "/data/cmdb/env_py36/lib/python3.6/site-packages/pymysql/connections.py", line 724, in _read_query_result
    result.read()
  File "/data/cmdb/env_py36/lib/python3.6/site-packages/pymysql/connections.py", line 1069, in read
    first_packet = self.connection._read_packet()
  File "/data/cmdb/env_py36/lib/python3.6/site-packages/pymysql/connections.py", line 676, in _read_packet
    packet.raise_for_error()
  File "/data/cmdb/env_py36/lib/python3.6/site-packages/pymysql/protocol.py", line 223, in raise_for_error
    err.raise_mysql_exception(self._data)
  File "/data/cmdb/env_py36/lib/python3.6/site-packages/pymysql/err.py", line 107, in raise_mysql_exception
    raise errorclass(errno, errval)
pymysql.err.ProgrammingError: (1146, "Table 'devops.view_menu' doesn't exist")

The above exception was the direct cause of the following exception:

Traceback (most recent call last):
  File "/data/cmdb/env_py36/lib/python3.6/site-packages/django/core/handlers/exception.py", line 41, in inner
    response = get_response(request)
  File "/data/cmdb/env_py36/lib/python3.6/site-packages/django/core/handlers/base.py", line 187, in _get_response
    response = self.process_exception_by_middleware(e, request)
  File "/data/cmdb/env_py36/lib/python3.6/site-packages/django/core/handlers/base.py", line 185, in _get_response
    response = wrapped_callback(request, *callback_args, **callback_kwargs)
  File "/data/cmdb/env_py36/lib/python3.6/site-packages/django/views/decorators/csrf.py", line 58, in wrapped_view
    return view_func(*args, **kwargs)
  File "/data/cmdb/env_py36/lib/python3.6/site-packages/rest_framework/viewsets.py", line 95, in view
    return self.dispatch(request, *args, **kwargs)
  File "/data/cmdb/env_py36/lib/python3.6/site-packages/rest_framework/views.py", line 494, in dispatch
    response = self.handle_exception(exc)
  File "/data/cmdb/env_py36/lib/python3.6/site-packages/rest_framework/views.py", line 454, in handle_exception
    self.raise_uncaught_exception(exc)
  File "/data/cmdb/env_py36/lib/python3.6/site-packages/rest_framework/views.py", line 491, in dispatch
    response = handler(request, *args, **kwargs)
  File "/data/cmdb/env_py36/lib/python3.6/site-packages/rest_framework/mixins.py", line 42, in list
    page = self.paginate_queryset(queryset)
  File "/data/cmdb/env_py36/lib/python3.6/site-packages/rest_framework/generics.py", line 173, in paginate_queryset
    return self.paginator.paginate_queryset(queryset, self.request, view=self)
  File "/data/cmdb/env_py36/lib/python3.6/site-packages/rest_framework/pagination.py", line 214, in paginate_queryset
    self.page = paginator.page(page_number)
  File "/data/cmdb/env_py36/lib/python3.6/site-packages/django/core/paginator.py", line 57, in page
    number = self.validate_number(number)
  File "/data/cmdb/env_py36/lib/python3.6/site-packages/django/core/paginator.py", line 46, in validate_number
    if number > self.num_pages:
  File "/data/cmdb/env_py36/lib/python3.6/site-packages/django/utils/functional.py", line 35, in __get__
    res = instance.__dict__[self.name] = self.func(instance)
  File "/data/cmdb/env_py36/lib/python3.6/site-packages/django/core/paginator.py", line 91, in num_pages
    if self.count == 0 and not self.allow_empty_first_page:
  File "/data/cmdb/env_py36/lib/python3.6/site-packages/django/utils/functional.py", line 35, in __get__
    res = instance.__dict__[self.name] = self.func(instance)
  File "/data/cmdb/env_py36/lib/python3.6/site-packages/django/core/paginator.py", line 79, in count
    return self.object_list.count()
  File "/data/cmdb/env_py36/lib/python3.6/site-packages/django/db/models/query.py", line 364, in count
    return self.query.get_count(using=self.db)
  File "/data/cmdb/env_py36/lib/python3.6/site-packages/django/db/models/sql/query.py", line 499, in get_count
    number = obj.get_aggregation(using, ['__count'])['__count']
  File "/data/cmdb/env_py36/lib/python3.6/site-packages/django/db/models/sql/query.py", line 480, in get_aggregation
    result = compiler.execute_sql(SINGLE)
  File "/data/cmdb/env_py36/lib/python3.6/site-packages/django/db/models/sql/compiler.py", line 899, in execute_sql
    raise original_exception
  File "/data/cmdb/env_py36/lib/python3.6/site-packages/django/db/models/sql/compiler.py", line 889, in execute_sql
    cursor.execute(sql, params)
  File "/data/cmdb/env_py36/lib/python3.6/site-packages/django/db/backends/utils.py", line 79, in execute
    return super(CursorDebugWrapper, self).execute(sql, params)
  File "/data/cmdb/env_py36/lib/python3.6/site-packages/django/db/backends/utils.py", line 64, in execute
    return self.cursor.execute(sql, params)
  File "/data/cmdb/env_py36/lib/python3.6/site-packages/django/db/utils.py", line 94, in __exit__
    six.reraise(dj_exc_type, dj_exc_value, traceback)
  File "/data/cmdb/env_py36/lib/python3.6/site-packages/django/utils/six.py", line 685, in reraise
    raise value.with_traceback(tb)
  File "/data/cmdb/env_py36/lib/python3.6/site-packages/django/db/backends/utils.py", line 64, in execute
    return self.cursor.execute(sql, params)
  File "/data/cmdb/env_py36/lib/python3.6/site-packages/django/db/backends/mysql/base.py", line 101, in execute
    return self.cursor.execute(query, args)
  File "/data/cmdb/env_py36/lib/python3.6/site-packages/pymysql/cursors.py", line 163, in execute
    result = self._query(query)
  File "/data/cmdb/env_py36/lib/python3.6/site-packages/pymysql/cursors.py", line 321, in _query
    conn.query(q)
  File "/data/cmdb/env_py36/lib/python3.6/site-packages/pymysql/connections.py", line 505, in query
    self._affected_rows = self._read_query_result(unbuffered=unbuffered)
  File "/data/cmdb/env_py36/lib/python3.6/site-packages/pymysql/connections.py", line 724, in _read_query_result
    result.read()
  File "/data/cmdb/env_py36/lib/python3.6/site-packages/pymysql/connections.py", line 1069, in read
    first_packet = self.connection._read_packet()
  File "/data/cmdb/env_py36/lib/python3.6/site-packages/pymysql/connections.py", line 676, in _read_packet
    packet.raise_for_error()
  File "/data/cmdb/env_py36/lib/python3.6/site-packages/pymysql/protocol.py", line 223, in raise_for_error
    err.raise_mysql_exception(self._data)
  File "/data/cmdb/env_py36/lib/python3.6/site-packages/pymysql/err.py", line 107, in raise_mysql_exception
    raise errorclass(errno, errval)
django.db.utils.ProgrammingError: (1146, "Table 'devops.view_menu' doesn't exist")
2020-11-03 14:45:27 [django.request:135] [ERROR] - Internal Server Error: /cabinet/
Traceback (most recent call last):
  File "/data/cmdb/env_py36/lib/python3.6/site-packages/django/db/backends/utils.py", line 64, in execute
    return self.cursor.execute(sql, params)
  File "/data/cmdb/env_py36/lib/python3.6/site-packages/django/db/backends/mysql/base.py", line 101, in execute
    return self.cursor.execute(query, args)
  File "/data/cmdb/env_py36/lib/python3.6/site-packages/pymysql/cursors.py", line 163, in execute
    result = self._query(query)
  File "/data/cmdb/env_py36/lib/python3.6/site-packages/pymysql/cursors.py", line 321, in _query
    conn.query(q)
  File "/data/cmdb/env_py36/lib/python3.6/site-packages/pymysql/connections.py", line 505, in query
    self._affected_rows = self._read_query_result(unbuffered=unbuffered)
  File "/data/cmdb/env_py36/lib/python3.6/site-packages/pymysql/connections.py", line 724, in _read_query_result
    result.read()
  File "/data/cmdb/env_py36/lib/python3.6/site-packages/pymysql/connections.py", line 1069, in read
    first_packet = self.connection._read_packet()
  File "/data/cmdb/env_py36/lib/python3.6/site-packages/pymysql/connections.py", line 676, in _read_packet
    packet.raise_for_error()
  File "/data/cmdb/env_py36/lib/python3.6/site-packages/pymysql/protocol.py", line 223, in raise_for_error
    err.raise_mysql_exception(self._data)
  File "/data/cmdb/env_py36/lib/python3.6/site-packages/pymysql/err.py", line 107, in raise_mysql_exception
    raise errorclass(errno, errval)
pymysql.err.ProgrammingError: (1146, "Table 'devops.resources_cabinet' doesn't exist")

The above exception was the direct cause of the following exception:

Traceback (most recent call last):
  File "/data/cmdb/env_py36/lib/python3.6/site-packages/django/core/handlers/exception.py", line 41, in inner
    response = get_response(request)
  File "/data/cmdb/env_py36/lib/python3.6/site-packages/django/core/handlers/base.py", line 187, in _get_response
    response = self.process_exception_by_middleware(e, request)
  File "/data/cmdb/env_py36/lib/python3.6/site-packages/django/core/handlers/base.py", line 185, in _get_response
    response = wrapped_callback(request, *callback_args, **callback_kwargs)
  File "/data/cmdb/env_py36/lib/python3.6/site-packages/django/views/decorators/csrf.py", line 58, in wrapped_view
    return view_func(*args, **kwargs)
  File "/data/cmdb/env_py36/lib/python3.6/site-packages/rest_framework/viewsets.py", line 95, in view
    return self.dispatch(request, *args, **kwargs)
  File "/data/cmdb/env_py36/lib/python3.6/site-packages/rest_framework/views.py", line 494, in dispatch
    response = self.handle_exception(exc)
  File "/data/cmdb/env_py36/lib/python3.6/site-packages/rest_framework/views.py", line 454, in handle_exception
    self.raise_uncaught_exception(exc)
  File "/data/cmdb/env_py36/lib/python3.6/site-packages/rest_framework/views.py", line 491, in dispatch
    response = handler(request, *args, **kwargs)
  File "/data/cmdb/env_py36/lib/python3.6/site-packages/rest_framework/mixins.py", line 42, in list
    page = self.paginate_queryset(queryset)
  File "/data/cmdb/env_py36/lib/python3.6/site-packages/rest_framework/generics.py", line 173, in paginate_queryset
    return self.paginator.paginate_queryset(queryset, self.request, view=self)
  File "/data/cmdb/env_py36/lib/python3.6/site-packages/rest_framework/pagination.py", line 214, in paginate_queryset
    self.page = paginator.page(page_number)
  File "/data/cmdb/env_py36/lib/python3.6/site-packages/django/core/paginator.py", line 57, in page
    number = self.validate_number(number)
  File "/data/cmdb/env_py36/lib/python3.6/site-packages/django/core/paginator.py", line 46, in validate_number
    if number > self.num_pages:
  File "/data/cmdb/env_py36/lib/python3.6/site-packages/django/utils/functional.py", line 35, in __get__
    res = instance.__dict__[self.name] = self.func(instance)
  File "/data/cmdb/env_py36/lib/python3.6/site-packages/django/core/paginator.py", line 91, in num_pages
    if self.count == 0 and not self.allow_empty_first_page:
  File "/data/cmdb/env_py36/lib/python3.6/site-packages/django/utils/functional.py", line 35, in __get__
    res = instance.__dict__[self.name] = self.func(instance)
  File "/data/cmdb/env_py36/lib/python3.6/site-packages/django/core/paginator.py", line 79, in count
    return self.object_list.count()
  File "/data/cmdb/env_py36/lib/python3.6/site-packages/django/db/models/query.py", line 364, in count
    return self.query.get_count(using=self.db)
  File "/data/cmdb/env_py36/lib/python3.6/site-packages/django/db/models/sql/query.py", line 499, in get_count
    number = obj.get_aggregation(using, ['__count'])['__count']
  File "/data/cmdb/env_py36/lib/python3.6/site-packages/django/db/models/sql/query.py", line 480, in get_aggregation
    result = compiler.execute_sql(SINGLE)
  File "/data/cmdb/env_py36/lib/python3.6/site-packages/django/db/models/sql/compiler.py", line 899, in execute_sql
    raise original_exception
  File "/data/cmdb/env_py36/lib/python3.6/site-packages/django/db/models/sql/compiler.py", line 889, in execute_sql
    cursor.execute(sql, params)
  File "/data/cmdb/env_py36/lib/python3.6/site-packages/django/db/backends/utils.py", line 79, in execute
    return super(CursorDebugWrapper, self).execute(sql, params)
  File "/data/cmdb/env_py36/lib/python3.6/site-packages/django/db/backends/utils.py", line 64, in execute
    return self.cursor.execute(sql, params)
  File "/data/cmdb/env_py36/lib/python3.6/site-packages/django/db/utils.py", line 94, in __exit__
    six.reraise(dj_exc_type, dj_exc_value, traceback)
  File "/data/cmdb/env_py36/lib/python3.6/site-packages/django/utils/six.py", line 685, in reraise
    raise value.with_traceback(tb)
  File "/data/cmdb/env_py36/lib/python3.6/site-packages/django/db/backends/utils.py", line 64, in execute
    return self.cursor.execute(sql, params)
  File "/data/cmdb/env_py36/lib/python3.6/site-packages/django/db/backends/mysql/base.py", line 101, in execute
    return self.cursor.execute(query, args)
  File "/data/cmdb/env_py36/lib/python3.6/site-packages/pymysql/cursors.py", line 163, in execute
    result = self._query(query)
  File "/data/cmdb/env_py36/lib/python3.6/site-packages/pymysql/cursors.py", line 321, in _query
    conn.query(q)
  File "/data/cmdb/env_py36/lib/python3.6/site-packages/pymysql/connections.py", line 505, in query
    self._affected_rows = self._read_query_result(unbuffered=unbuffered)
  File "/data/cmdb/env_py36/lib/python3.6/site-packages/pymysql/connections.py", line 724, in _read_query_result
    result.read()
  File "/data/cmdb/env_py36/lib/python3.6/site-packages/pymysql/connections.py", line 1069, in read
    first_packet = self.connection._read_packet()
  File "/data/cmdb/env_py36/lib/python3.6/site-packages/pymysql/connections.py", line 676, in _read_packet
    packet.raise_for_error()
  File "/data/cmdb/env_py36/lib/python3.6/site-packages/pymysql/protocol.py", line 223, in raise_for_error
    err.raise_mysql_exception(self._data)
  File "/data/cmdb/env_py36/lib/python3.6/site-packages/pymysql/err.py", line 107, in raise_mysql_exception
    raise errorclass(errno, errval)
django.db.utils.ProgrammingError: (1146, "Table 'devops.resources_cabinet' doesn't exist")
